<sdf version='1.7'>
  <world name='default'>
    <model name='ground_plane'>
      <static>1</static>
      <link name='link'>
        <collision name='collision'>
          <geometry>
            <plane>
              <normal>0 0 1</normal>
              <size>100 100</size>
            </plane>
          </geometry>
          <surface>
            <contact>
              <collide_bitmask>65535</collide_bitmask>
              <ode/>
            </contact>
            <friction>
              <ode>
                <mu>100</mu>
                <mu2>50</mu2>
              </ode>
              <torsional>
                <ode/>
              </torsional>
            </friction>
            <bounce/>
          </surface>
          <max_contacts>10</max_contacts>
        </collision>
        <visual name='visual'>
          <cast_shadows>0</cast_shadows>
          <geometry>
            <plane>
              <normal>0 0 1</normal>
              <size>100 100</size>
            </plane>
          </geometry>
          <material>
            <script>
              <uri>file://media/materials/scripts/gazebo.material</uri>
              <name>Gazebo/Grey</name>
            </script>
          </material>
        </visual>
        <self_collide>0</self_collide>
        <enable_wind>0</enable_wind>
        <kinematic>0</kinematic>
      </link>
    </model>
    <light name='sun' type='directional'>
      <cast_shadows>1</cast_shadows>
      <pose>0 0 10 0 -0 0</pose>
      <diffuse>0.8 0.8 0.8 1</diffuse>
      <specular>0.2 0.2 0.2 1</specular>
      <attenuation>
        <range>1000</range>
        <constant>0.9</constant>
        <linear>0.01</linear>
        <quadratic>0.001</quadratic>
      </attenuation>
      <direction>-0.5 0.1 -0.9</direction>
      <spot>
        <inner_angle>0</inner_angle>
        <outer_angle>0</outer_angle>
        <falloff>0</falloff>
      </spot>
    </light>
    <physics type='ode'>
      <real_time_update_rate>1000</real_time_update_rate>
      <max_step_size>0.001</max_step_size>
      <real_time_factor>1</real_time_factor>
    </physics>
    <gravity>0 0 0</gravity>
    <gui fullscreen='0'>
      <camera name='user_camera'>
        <pose>2.36956 0.999462 1.14116 0 0.2858 -2.60579</pose>
        <view_controller>orbit</view_controller>
        <projection_type>perspective</projection_type>
      </camera>
    </gui>
    <magnetic_field>6e-06 2.3e-05 -4.2e-05</magnetic_field>
    <atmosphere type='adiabatic'/>
    <scene>
      <ambient>0.4 0.4 0.4 1</ambient>
      <background>0.7 0.7 0.7 1</background>
      <shadows>1</shadows>
    </scene>
    <wind/>
    <spherical_coordinates>
      <surface_model>EARTH_WGS84</surface_model>
      <latitude_deg>0</latitude_deg>
      <longitude_deg>0</longitude_deg>
      <elevation>0</elevation>
      <heading_deg>0</heading_deg>
    </spherical_coordinates>
    <model name='panda'>
      <joint name='panda_to_world' type='fixed'>
        <pose relative_to='__model__'>0 0 0 0 -0 0</pose>
        <parent>world</parent>
        <child>panda_link0</child>
      </joint>
      <link name='panda_link0'>
        <pose relative_to='panda_to_world'>0 0 0 0 -0 0</pose>
        <inertial>
          <pose>0 0 0 0 -0 0</pose>
          <mass>3.06</mass>
          <inertia>
            <ixx>0.3</ixx>
            <ixy>0</ixy>
            <ixz>0</ixz>
            <iyy>0.3</iyy>
            <iyz>0</iyz>
            <izz>0.3</izz>
          </inertia>
        </inertial>
        <collision name='panda_link0_collision'>
          <pose>0 0 0 0 -0 0</pose>
          <geometry>
            <mesh>
              <scale>1 1 1</scale>
              <uri>/home/pete/catkin_ws/src/franka_panda_description/meshes/collision/link0.stl</uri>
            </mesh>
          </geometry>
          <max_contacts>10</max_contacts>
          <surface>
            <contact>
              <ode/>
            </contact>
            <bounce/>
            <friction>
              <torsional>
                <ode/>
              </torsional>
              <ode/>
            </friction>
          </surface>
        </collision>
        <visual name='panda_link0_visual'>
          <pose>0 0 0 0 -0 0</pose>
          <geometry>
            <mesh>
              <scale>1 1 1</scale>
              <uri>/home/pete/catkin_ws/src/franka_panda_description/meshes/visual/link0.dae</uri>
            </mesh>
          </geometry>
        </visual>
        <self_collide>0</self_collide>
        <enable_wind>0</enable_wind>
        <kinematic>0</kinematic>
      </link>
      <joint name='panda_joint1' type='revolute'>
        <pose relative_to='panda_link0'>0 0 0.333 0 -0 0</pose>
        <parent>panda_link0</parent>
        <child>panda_link1</child>
        <axis>
          <xyz>0 0 1</xyz>
          <limit>
            <lower>-2.8973</lower>
            <upper>2.8973</upper>
            <effort>87</effort>
            <velocity>2.175</velocity>
          </limit>
          <dynamics>
            <damping>10</damping>
            <friction>5</friction>
            <spring_reference>0</spring_reference>
            <spring_stiffness>0</spring_stiffness>
          </dynamics>
        </axis>
        <physics>
          <provide_feedback>1</provide_feedback>
          <ode>
            <implicit_spring_damper>1</implicit_spring_damper>
            <cfm_damping>1</cfm_damping>
            <limit>
              <cfm>0</cfm>
              <erp>0.2</erp>
            </limit>
            <provide_feedback>1</provide_feedback>
          </ode>
        </physics>
      </joint>
      <link name='panda_link1'>
        <pose relative_to='panda_joint1'>0 0 0 0 -0 0</pose>
        <inertial>
          <pose>0.003875 0.002081 -0.175 0 -0 0</pose>
          <mass>4.97068</mass>
          <inertia>
            <ixx>0.70337</ixx>
            <ixy>-0.000139</ixy>
            <ixz>0.006772</ixz>
            <iyy>0.70661</iyy>
            <iyz>0.019169</iyz>
            <izz>0.009117</izz>
          </inertia>
        </inertial>
        <collision name='panda_link1_collision'>
          <pose>0 0 0 0 -0 0</pose>
          <geometry>
            <mesh>
              <scale>1 1 1</scale>
              <uri>/home/pete/catkin_ws/src/franka_panda_description/meshes/collision/link1.stl</uri>
            </mesh>
          </geometry>
          <surface>
            <contact>
              <ode/>
            </contact>
            <friction>
              <ode/>
              <torsional>
                <ode/>
              </torsional>
            </friction>
            <bounce/>
          </surface>
          <max_contacts>10</max_contacts>
        </collision>
        <visual name='panda_link1_visual'>
          <pose>0 0 0 0 -0 0</pose>
          <geometry>
            <mesh>
              <scale>1 1 1</scale>
              <uri>/home/pete/catkin_ws/src/franka_panda_description/meshes/visual/link1.dae</uri>
            </mesh>
          </geometry>
        </visual>
        <velocity_decay/>
        <self_collide>1</self_collide>
        <gravity>1</gravity>
        <velocity_decay/>
        <sensor name='panda_link1_contact' type='contact'>
          <update_rate>50</update_rate>
          <always_on>1</always_on>
          <contact>
            <collision>panda_link1_collision</collision>
            <topic>__default_topic__</topic>
          </contact>
          <plugin name='link1_bumper' filename='libgazebo_ros_bumper.so'>
            <bumperTopicName>panda_link1_collision</bumperTopicName>
            <frameName>panda_link1</frameName>
            <robotNamespace>/</robotNamespace>
          </plugin>
        </sensor>
        <enable_wind>0</enable_wind>
        <kinematic>0</kinematic>
      </link>
      <joint name='panda_joint2' type='revolute'>
        <pose relative_to='panda_link1'>0 0 0 -1.5708 0 0</pose>
        <parent>panda_link1</parent>
        <child>panda_link2</child>
        <axis>
          <xyz>0 0 1</xyz>
          <limit>
            <lower>-1.7628</lower>
            <upper>1.7628</upper>
            <effort>87</effort>
            <velocity>2.175</velocity>
          </limit>
          <dynamics>
            <damping>5</damping>
            <friction>2</friction>
            <spring_reference>0</spring_reference>
            <spring_stiffness>0</spring_stiffness>
          </dynamics>
        </axis>
        <physics>
          <provide_feedback>1</provide_feedback>
          <ode>
            <implicit_spring_damper>1</implicit_spring_damper>
            <cfm_damping>1</cfm_damping>
            <limit>
              <cfm>0</cfm>
              <erp>0.2</erp>
            </limit>
            <provide_feedback>1</provide_feedback>
          </ode>
        </physics>
      </joint>
      <link name='panda_link2'>
        <pose relative_to='panda_joint2'>0 0 0 0 -0 0</pose>
        <inertial>
          <pose>-0.003141 -0.02872 0.003495 0 -0 0</pose>
          <mass>0.646926</mass>
          <inertia>
            <ixx>0.007962</ixx>
            <ixy>-0.003925</ixy>
            <ixz>0.010254</ixz>
            <iyy>0.02811</iyy>
            <iyz>0.000704</iyz>
            <izz>0.025995</izz>
          </inertia>
        </inertial>
        <collision name='panda_link2_collision'>
          <pose>0 0 0 0 -0 0</pose>
          <geometry>
            <mesh>
              <scale>1 1 1</scale>
              <uri>/home/pete/catkin_ws/src/franka_panda_description/meshes/collision/link2.stl</uri>
            </mesh>
          </geometry>
          <surface>
            <contact>
              <ode/>
            </contact>
            <friction>
              <ode/>
              <torsional>
                <ode/>
              </torsional>
            </friction>
            <bounce/>
          </surface>
          <max_contacts>10</max_contacts>
        </collision>
        <visual name='panda_link2_visual'>
          <pose>0 0 0 0 -0 0</pose>
          <geometry>
            <mesh>
              <scale>1 1 1</scale>
              <uri>/home/pete/catkin_ws/src/franka_panda_description/meshes/visual/link2.dae</uri>
            </mesh>
          </geometry>
        </visual>
        <velocity_decay/>
        <self_collide>1</self_collide>
        <gravity>1</gravity>
        <velocity_decay/>
        <sensor name='panda_link2_contact' type='contact'>
          <update_rate>50</update_rate>
          <always_on>1</always_on>
          <contact>
            <collision>panda_link2_collision</collision>
            <topic>__default_topic__</topic>
          </contact>
          <plugin name='link2_bumper' filename='libgazebo_ros_bumper.so'>
            <bumperTopicName>panda_link2_collision</bumperTopicName>
            <frameName>panda_link2</frameName>
            <robotNamespace>/</robotNamespace>
          </plugin>
        </sensor>
        <enable_wind>0</enable_wind>
        <kinematic>0</kinematic>
      </link>
      <joint name='panda_joint3' type='revolute'>
        <pose relative_to='panda_link2'>0 -0.316 0 1.5708 -0 0</pose>
        <parent>panda_link2</parent>
        <child>panda_link3</child>
        <axis>
          <xyz>0 0 1</xyz>
          <limit>
            <lower>-2.8973</lower>
            <upper>2.8973</upper>
            <effort>87</effort>
            <velocity>2.175</velocity>
          </limit>
          <dynamics>
            <damping>5</damping>
            <friction>2</friction>
            <spring_reference>0</spring_reference>
            <spring_stiffness>0</spring_stiffness>
          </dynamics>
        </axis>
        <physics>
          <provide_feedback>1</provide_feedback>
          <ode>
            <implicit_spring_damper>1</implicit_spring_damper>
            <cfm_damping>1</cfm_damping>
            <limit>
              <cfm>0</cfm>
              <erp>0.2</erp>
            </limit>
            <provide_feedback>1</provide_feedback>
          </ode>
        </physics>
      </joint>
      <link name='panda_link3'>
        <pose relative_to='panda_joint3'>0 0 0 0 -0 0</pose>
        <inertial>
          <pose>0.027518 0.039252 -0.066502 0 -0 0</pose>
          <mass>3.2286</mass>
          <inertia>
            <ixx>0.037242</ixx>
            <ixy>-0.004761</ixy>
            <ixz>-0.011396</ixz>
            <iyy>0.036155</iyy>
            <iyz>-0.012805</iyz>
            <izz>0.01083</izz>
          </inertia>
        </inertial>
        <collision name='panda_link3_collision'>
          <pose>0 0 0 0 -0 0</pose>
          <geometry>
            <mesh>
              <scale>1 1 1</scale>
              <uri>/home/pete/catkin_ws/src/franka_panda_description/meshes/collision/link3.stl</uri>
            </mesh>
          </geometry>
          <surface>
            <contact>
              <ode/>
            </contact>
            <friction>
              <ode/>
              <torsional>
                <ode/>
              </torsional>
            </friction>
            <bounce/>
          </surface>
          <max_contacts>10</max_contacts>
        </collision>
        <visual name='panda_link3_visual'>
          <pose>0 0 0 0 -0 0</pose>
          <geometry>
            <mesh>
              <scale>1 1 1</scale>
              <uri>/home/pete/catkin_ws/src/franka_panda_description/meshes/visual/link3.dae</uri>
            </mesh>
          </geometry>
        </visual>
        <velocity_decay/>
        <self_collide>1</self_collide>
        <gravity>1</gravity>
        <velocity_decay/>
        <sensor name='panda_link3_contact' type='contact'>
          <update_rate>50</update_rate>
          <always_on>1</always_on>
          <contact>
            <collision>panda_link3_collision</collision>
            <topic>__default_topic__</topic>
          </contact>
          <plugin name='link3_bumper' filename='libgazebo_ros_bumper.so'>
            <bumperTopicName>panda_link3_collision</bumperTopicName>
            <frameName>panda_link3</frameName>
            <robotNamespace>/</robotNamespace>
          </plugin>
        </sensor>
        <enable_wind>0</enable_wind>
        <kinematic>0</kinematic>
      </link>
      <joint name='panda_joint4' type='revolute'>
        <pose relative_to='panda_link3'>0.0825 0 0 1.5708 -0 0</pose>
        <parent>panda_link3</parent>
        <child>panda_link4</child>
        <axis>
          <xyz>0 0 1</xyz>
          <limit>
            <lower>-3.0718</lower>
            <upper>-0.0698</upper>
            <effort>87</effort>
            <velocity>2.175</velocity>
          </limit>
          <dynamics>
            <damping>1</damping>
            <friction>0.5</friction>
            <spring_reference>0</spring_reference>
            <spring_stiffness>0</spring_stiffness>
          </dynamics>
        </axis>
        <physics>
          <provide_feedback>1</provide_feedback>
          <ode>
            <implicit_spring_damper>1</implicit_spring_damper>
            <cfm_damping>1</cfm_damping>
            <limit>
              <cfm>0</cfm>
              <erp>0.2</erp>
            </limit>
            <provide_feedback>1</provide_feedback>
          </ode>
        </physics>
      </joint>
      <link name='panda_link4'>
        <pose relative_to='panda_joint4'>0 0 0 0 -0 0</pose>
        <inertial>
          <pose>-0.05317 0.104419 0.027454 0 -0 0</pose>
          <mass>3.5879</mass>
          <inertia>
            <ixx>0.025853</ixx>
            <ixy>0.007796</ixy>
            <ixz>-0.001332</ixz>
            <iyy>0.019552</iyy>
            <iyz>0.008641</iyz>
            <izz>0.028323</izz>
          </inertia>
        </inertial>
        <collision name='panda_link4_collision'>
          <pose>0 0 0 0 -0 0</pose>
          <geometry>
            <mesh>
              <scale>1 1 1</scale>
              <uri>/home/pete/catkin_ws/src/franka_panda_description/meshes/collision/link4.stl</uri>
            </mesh>
          </geometry>
          <surface>
            <contact>
              <ode/>
            </contact>
            <friction>
              <ode/>
              <torsional>
                <ode/>
              </torsional>
            </friction>
            <bounce/>
          </surface>
          <max_contacts>10</max_contacts>
        </collision>
        <visual name='panda_link4_visual'>
          <pose>0 0 0 0 -0 0</pose>
          <geometry>
            <mesh>
              <scale>1 1 1</scale>
              <uri>/home/pete/catkin_ws/src/franka_panda_description/meshes/visual/link4.dae</uri>
            </mesh>
          </geometry>
        </visual>
        <velocity_decay/>
        <self_collide>1</self_collide>
        <gravity>1</gravity>
        <velocity_decay/>
        <sensor name='panda_link4_contact' type='contact'>
          <update_rate>50</update_rate>
          <always_on>1</always_on>
          <contact>
            <collision>panda_link4_collision</collision>
            <topic>__default_topic__</topic>
          </contact>
          <plugin name='link4_bumper' filename='libgazebo_ros_bumper.so'>
            <bumperTopicName>panda_link4_collision</bumperTopicName>
            <frameName>panda_link4</frameName>
            <robotNamespace>/</robotNamespace>
          </plugin>
        </sensor>
        <enable_wind>0</enable_wind>
        <kinematic>0</kinematic>
      </link>
      <joint name='panda_joint5' type='revolute'>
        <pose relative_to='panda_link4'>-0.0825 0.384 0 -1.5708 0 0</pose>
        <parent>panda_link4</parent>
        <child>panda_link5</child>
        <axis>
          <xyz>0 0 1</xyz>
          <limit>
            <lower>-2.8973</lower>
            <upper>2.8973</upper>
            <effort>12</effort>
            <velocity>2.61</velocity>
          </limit>
          <dynamics>
            <damping>2</damping>
            <friction>1</friction>
            <spring_reference>0</spring_reference>
            <spring_stiffness>0</spring_stiffness>
          </dynamics>
        </axis>
        <physics>
          <provide_feedback>1</provide_feedback>
          <ode>
            <implicit_spring_damper>1</implicit_spring_damper>
            <cfm_damping>1</cfm_damping>
            <limit>
              <cfm>0</cfm>
              <erp>0.2</erp>
            </limit>
            <provide_feedback>1</provide_feedback>
          </ode>
        </physics>
      </joint>
      <link name='panda_link5'>
        <pose relative_to='panda_joint5'>0 0 0 0 -0 0</pose>
        <inertial>
          <pose>-0.011953 0.041065 -0.038437 0 -0 0</pose>
          <mass>1.22595</mass>
          <inertia>
            <ixx>0.035549</ixx>
            <ixy>-0.002117</ixy>
            <ixz>-0.004037</ixz>
            <iyy>0.029474</iyy>
            <iyz>0.000229</iyz>
            <izz>0.008627</izz>
          </inertia>
        </inertial>
        <collision name='panda_link5_collision'>
          <pose>0 0 0 0 -0 0</pose>
          <geometry>
            <mesh>
              <scale>1 1 1</scale>
              <uri>/home/pete/catkin_ws/src/franka_panda_description/meshes/collision/link5.stl</uri>
            </mesh>
          </geometry>
          <surface>
            <contact>
              <ode/>
            </contact>
            <friction>
              <ode/>
              <torsional>
                <ode/>
              </torsional>
            </friction>
            <bounce/>
          </surface>
          <max_contacts>10</max_contacts>
        </collision>
        <visual name='panda_link5_visual'>
          <pose>0 0 0 0 -0 0</pose>
          <geometry>
            <mesh>
              <scale>1 1 1</scale>
              <uri>/home/pete/catkin_ws/src/franka_panda_description/meshes/visual/link5.dae</uri>
            </mesh>
          </geometry>
        </visual>
        <velocity_decay/>
        <self_collide>1</self_collide>
        <gravity>1</gravity>
        <velocity_decay/>
        <sensor name='panda_link5_contact' type='contact'>
          <update_rate>50</update_rate>
          <always_on>1</always_on>
          <contact>
            <collision>panda_link5_collision</collision>
            <topic>__default_topic__</topic>
          </contact>
          <plugin name='link5_bumper' filename='libgazebo_ros_bumper.so'>
            <bumperTopicName>panda_link5_collision</bumperTopicName>
            <frameName>panda_link5</frameName>
            <robotNamespace>/</robotNamespace>
          </plugin>
        </sensor>
        <enable_wind>0</enable_wind>
        <kinematic>0</kinematic>
      </link>
      <joint name='panda_joint6' type='revolute'>
        <pose relative_to='panda_link5'>0 0 0 1.5708 -0 0</pose>
        <parent>panda_link5</parent>
        <child>panda_link6</child>
        <axis>
          <xyz>0 0 1</xyz>
          <limit>
            <lower>-0.0175</lower>
            <upper>3.7525</upper>
            <effort>12</effort>
            <velocity>2.61</velocity>
          </limit>
          <dynamics>
            <damping>1</damping>
            <friction>0.5</friction>
            <spring_reference>0</spring_reference>
            <spring_stiffness>0</spring_stiffness>
          </dynamics>
        </axis>
        <physics>
          <provide_feedback>1</provide_feedback>
          <ode>
            <implicit_spring_damper>1</implicit_spring_damper>
            <cfm_damping>1</cfm_damping>
            <limit>
              <cfm>0</cfm>
              <erp>0.2</erp>
            </limit>
            <provide_feedback>1</provide_feedback>
          </ode>
        </physics>
      </joint>
      <link name='panda_link6'>
        <pose relative_to='panda_joint6'>0 0 0 0 -0 0</pose>
        <inertial>
          <pose>0.060149 -0.014117 -0.010517 0 -0 0</pose>
          <mass>1.66656</mass>
          <inertia>
            <ixx>0.001964</ixx>
            <ixy>0.000109</ixy>
            <ixz>-0.001158</ixz>
            <iyy>0.004354</iyy>
            <iyz>0.000341</iyz>
            <izz>0.005433</izz>
          </inertia>
        </inertial>
        <collision name='panda_link6_collision'>
          <pose>0 0 0 0 -0 0</pose>
          <geometry>
            <mesh>
              <scale>1 1 1</scale>
              <uri>/home/pete/catkin_ws/src/franka_panda_description/meshes/collision/link6.stl</uri>
            </mesh>
          </geometry>
          <surface>
            <contact>
              <ode/>
            </contact>
            <friction>
              <ode/>
              <torsional>
                <ode/>
              </torsional>
            </friction>
            <bounce/>
          </surface>
          <max_contacts>10</max_contacts>
        </collision>
        <visual name='panda_link6_visual'>
          <pose>0 0 0 0 -0 0</pose>
          <geometry>
            <mesh>
              <scale>1 1 1</scale>
              <uri>/home/pete/catkin_ws/src/franka_panda_description/meshes/visual/link6.dae</uri>
            </mesh>
          </geometry>
        </visual>
        <velocity_decay/>
        <self_collide>1</self_collide>
        <gravity>1</gravity>
        <velocity_decay/>
        <sensor name='panda_link6_contact' type='contact'>
          <update_rate>50</update_rate>
          <always_on>1</always_on>
          <contact>
            <collision>panda_link6_collision</collision>
            <topic>__default_topic__</topic>
          </contact>
          <plugin name='link6_bumper' filename='libgazebo_ros_bumper.so'>
            <bumperTopicName>panda_link6_collision</bumperTopicName>
            <frameName>panda_link6</frameName>
            <robotNamespace>/</robotNamespace>
          </plugin>
        </sensor>
        <enable_wind>0</enable_wind>
        <kinematic>0</kinematic>
      </link>
      <joint name='panda_joint7' type='revolute'>
        <pose relative_to='panda_link6'>0.088 0 0 1.5708 -0 0</pose>
        <parent>panda_link6</parent>
        <child>panda_link7</child>
        <axis>
          <xyz>0 0 1</xyz>
          <limit>
            <lower>-2.8973</lower>
            <upper>2.8973</upper>
            <effort>12</effort>
            <velocity>2.61</velocity>
          </limit>
          <dynamics>
            <damping>1</damping>
            <friction>0.5</friction>
            <spring_reference>0</spring_reference>
            <spring_stiffness>0</spring_stiffness>
          </dynamics>
        </axis>
        <physics>
          <provide_feedback>1</provide_feedback>
          <ode>
            <implicit_spring_damper>1</implicit_spring_damper>
            <cfm_damping>1</cfm_damping>
            <limit>
              <cfm>0</cfm>
              <erp>0.2</erp>
            </limit>
            <provide_feedback>1</provide_feedback>
          </ode>
        </physics>
        <sensor name='panda_joint7_force_torque' type='force_torque'>
          <always_on>1</always_on>
          <visualize>0</visualize>
          <force_torque>
            <frame>sensor</frame>
            <measure_direction>child_to_parent</measure_direction>
          </force_torque>
        </sensor>
      </joint>
      <link name='panda_link7'>
        <pose relative_to='panda_joint7'>0 0 0 0 -0 0</pose>
        <inertial>
          <pose>0.005815 -0.001597 0.097957 0 -0 0</pose>
          <mass>1.46552</mass>
          <inertia>
            <ixx>0.0170713</ixx>
            <ixy>-0.00160235</ixy>
            <ixz>-0.000943568</ixz>
            <iyy>0.0146046</iyy>
            <iyz>-0.000883539</iyz>
            <izz>0.00842183</izz>
          </inertia>
        </inertial>
        <collision name='panda_link7_collision'>
          <pose>0 0 0 0 -0 0</pose>
          <geometry>
            <mesh>
              <scale>1 1 1</scale>
              <uri>/home/pete/catkin_ws/src/franka_panda_description/meshes/collision/link7.stl</uri>
            </mesh>
          </geometry>
          <surface>
            <contact>
              <ode/>
            </contact>
            <friction>
              <ode/>
              <torsional>
                <ode/>
              </torsional>
            </friction>
            <bounce/>
          </surface>
          <max_contacts>10</max_contacts>
        </collision>
        <collision name='panda_link7_fixed_joint_lump__panda_hand_collision_1'>
          <pose>0 0 0.107 0 0 -0.785398</pose>
          <geometry>
            <mesh>
              <scale>1 1 1</scale>
              <uri>/home/pete/catkin_ws/src/franka_panda_description/meshes/collision/hand.stl</uri>
            </mesh>
          </geometry>
          <max_contacts>10</max_contacts>
          <surface>
            <contact>
              <ode/>
            </contact>
            <bounce/>
            <friction>
              <torsional>
                <ode/>
              </torsional>
              <ode/>
            </friction>
          </surface>
        </collision>
        <visual name='panda_link7_visual'>
          <pose>0 0 0 0 -0 0</pose>
          <geometry>
            <mesh>
              <scale>1 1 1</scale>
              <uri>/home/pete/catkin_ws/src/franka_panda_description/meshes/visual/link7.dae</uri>
            </mesh>
          </geometry>
        </visual>
        <visual name='panda_link7_fixed_joint_lump__panda_hand_visual_1'>
          <pose>0 0 0.107 0 0 -0.785398</pose>
          <geometry>
            <mesh>
              <scale>1 1 1</scale>
              <uri>/home/pete/catkin_ws/src/franka_panda_description/meshes/visual/hand.dae</uri>
            </mesh>
          </geometry>
        </visual>
        <velocity_decay/>
        <self_collide>1</self_collide>
        <gravity>1</gravity>
        <velocity_decay/>
        <sensor name='panda_link7_contact' type='contact'>
          <update_rate>50</update_rate>
          <always_on>1</always_on>
          <contact>
            <collision>panda_link7_collision</collision>
            <topic>__default_topic__</topic>
          </contact>
          <plugin name='link7_bumper' filename='libgazebo_ros_bumper.so'>
            <bumperTopicName>panda_link7_collision</bumperTopicName>
            <frameName>panda_link7</frameName>
            <robotNamespace>/</robotNamespace>
          </plugin>
        </sensor>
        <enable_wind>0</enable_wind>
        <kinematic>0</kinematic>
      </link>
      <joint name='panda_finger_joint1' type='prismatic'>
        <pose relative_to='panda_link7'>0 0 0.1654 0 0 -0.785398</pose>
        <parent>panda_link7</parent>
        <child>panda_leftfinger</child>
        <axis>
          <xyz>0 1 0</xyz>
          <limit>
            <lower>0</lower>
            <upper>0.04</upper>
            <effort>20</effort>
            <velocity>0.2</velocity>
          </limit>
          <dynamics>
            <damping>500</damping>
            <friction>0</friction>
            <spring_reference>0</spring_reference>
            <spring_stiffness>0</spring_stiffness>
          </dynamics>
        </axis>
        <physics>
          <provide_feedback>1</provide_feedback>
          <ode>
            <implicit_spring_damper>1</implicit_spring_damper>
            <cfm_damping>1</cfm_damping>
            <limit>
              <cfm>0</cfm>
              <erp>0.2</erp>
            </limit>
            <provide_feedback>1</provide_feedback>
          </ode>
        </physics>
      </joint>
      <link name='panda_leftfinger'>
        <pose relative_to='panda_finger_joint1'>0 0 0 0 -0 0</pose>
        <inertial>
          <pose>0 0.014564 0.022794 0 -0 0</pose>
          <mass>0.1</mass>
          <inertia>
            <ixx>3.01221e-05</ixx>
            <ixy>0</ixy>
            <ixz>0</ixz>
            <iyy>2.95874e-05</iyy>
            <iyz>0</iyz>
            <izz>6.95125e-06</izz>
          </inertia>
        </inertial>
        <collision name='panda_leftfinger_collision'>
          <pose>0 0 0 0 -0 0</pose>
          <geometry>
            <mesh>
              <scale>1 1 1</scale>
              <uri>/home/pete/catkin_ws/src/franka_panda_description/meshes/collision/finger.stl</uri>
            </mesh>
          </geometry>
          <surface>
            <contact>
              <ode/>
            </contact>
            <friction>
              <ode/>
              <torsional>
                <ode/>
              </torsional>
            </friction>
            <bounce/>
          </surface>
          <max_contacts>10</max_contacts>
        </collision>
        <visual name='panda_leftfinger_visual'>
          <pose>0 0 0 0 -0 0</pose>
          <geometry>
            <mesh>
              <scale>1 1 1</scale>
              <uri>/home/pete/catkin_ws/src/franka_panda_description/meshes/visual/finger.dae</uri>
            </mesh>
          </geometry>
        </visual>
        <gravity>1</gravity>
        <velocity_decay/>
        <sensor name='panda_leftfinger_contact' type='contact'>
          <update_rate>50</update_rate>
          <always_on>1</always_on>
          <contact>
            <collision>panda_leftfinger_collision</collision>
            <topic>__default_topic__</topic>
          </contact>
          <plugin name='leftfinger_bumper' filename='libgazebo_ros_bumper.so'>
            <bumperTopicName>panda_leftfinger_collision</bumperTopicName>
            <frameName>panda_leftfinger</frameName>
            <robotNamespace>/</robotNamespace>
          </plugin>
        </sensor>
        <self_collide>0</self_collide>
        <enable_wind>0</enable_wind>
        <kinematic>0</kinematic>
      </link>
      <joint name='panda_finger_joint2' type='prismatic'>
        <pose relative_to='panda_link7'>0 0 0.1654 0 0 -0.785398</pose>
        <parent>panda_link7</parent>
        <child>panda_rightfinger</child>
        <axis>
          <xyz>0 -1 0</xyz>
          <limit>
            <lower>0</lower>
            <upper>0.04</upper>
            <effort>20</effort>
            <velocity>0.2</velocity>
          </limit>
          <dynamics>
            <damping>500</damping>
            <friction>0</friction>
            <spring_reference>0</spring_reference>
            <spring_stiffness>0</spring_stiffness>
          </dynamics>
        </axis>
        <physics>
          <provide_feedback>1</provide_feedback>
          <ode>
            <implicit_spring_damper>1</implicit_spring_damper>
            <cfm_damping>1</cfm_damping>
            <limit>
              <cfm>0</cfm>
              <erp>0.2</erp>
            </limit>
            <provide_feedback>1</provide_feedback>
          </ode>
        </physics>
      </joint>
      <link name='panda_rightfinger'>
        <pose relative_to='panda_finger_joint2'>0 0 0 0 -0 0</pose>
        <inertial>
          <pose>0 -0.014564 0.022794 0 -0 3.14159</pose>
          <mass>0.1</mass>
          <inertia>
            <ixx>3.01221e-05</ixx>
            <ixy>0</ixy>
            <ixz>0</ixz>
            <iyy>2.95874e-05</iyy>
            <iyz>0</iyz>
            <izz>6.95125e-06</izz>
          </inertia>
        </inertial>
        <collision name='panda_rightfinger_collision'>
          <pose>0 0 0 0 -0 3.14159</pose>
          <geometry>
            <mesh>
              <scale>1 1 1</scale>
              <uri>/home/pete/catkin_ws/src/franka_panda_description/meshes/collision/finger.stl</uri>
            </mesh>
          </geometry>
          <surface>
            <contact>
              <ode/>
            </contact>
            <friction>
              <ode/>
              <torsional>
                <ode/>
              </torsional>
            </friction>
            <bounce/>
          </surface>
          <max_contacts>10</max_contacts>
        </collision>
        <visual name='panda_rightfinger_visual'>
          <pose>0 0 0 0 -0 3.14159</pose>
          <geometry>
            <mesh>
              <scale>1 1 1</scale>
              <uri>/home/pete/catkin_ws/src/franka_panda_description/meshes/visual/finger.dae</uri>
            </mesh>
          </geometry>
        </visual>
        <gravity>1</gravity>
        <velocity_decay/>
        <sensor name='panda_rightfinger_contact' type='contact'>
          <update_rate>50</update_rate>
          <always_on>1</always_on>
          <contact>
            <collision>panda_rightfinger_collision</collision>
            <topic>__default_topic__</topic>
          </contact>
          <plugin name='rightfinger_bumper' filename='libgazebo_ros_bumper.so'>
            <bumperTopicName>panda_rightfinger_collision</bumperTopicName>
            <frameName>panda_rightfinger</frameName>
            <robotNamespace>/</robotNamespace>
          </plugin>
        </sensor>
        <self_collide>0</self_collide>
        <enable_wind>0</enable_wind>
        <kinematic>0</kinematic>
      </link>
      <plugin name='ft_sensor' filename='libgazebo_ros_ft_sensor.so'>
        <updateRate>30.0</updateRate>
        <topicName>/gazebo/robot/wrist/ft</topicName>
        <jointName>panda_joint7</jointName>
        <robotNamespace>/</robotNamespace>
      </plugin>
      <static>0</static>
      <plugin name='panda_ros_control' filename='libpanda_gazebo_ros_control.so'>
        <robotNamespace/>
        <robotSimType>panda_gazebo/PandaRobotHWSim</robotSimType>
        <controlPeriod>0.001</controlPeriod>
        <eStopTopic>sim_estop</eStopTopic>
      </plugin>
      <pose>0 0 0 0 -0 0</pose>
    </model>
    <state world_name='default'>
      <sim_time>44 162000000</sim_time>
      <real_time>14 560715122</real_time>
      <wall_time>1630664623 812376244</wall_time>
      <iterations>14198</iterations>
      <model name='ground_plane'>
        <pose>0 0 0 0 -0 0</pose>
        <scale>1 1 1</scale>
        <link name='link'>
          <pose>0 0 0 0 -0 0</pose>
          <velocity>0 0 0 0 -0 0</velocity>
          <acceleration>0 0 0 0 -0 0</acceleration>
          <wrench>0 0 0 0 -0 0</wrench>
        </link>
      </model>
      <model name='panda'>
        <pose>0 0 3.3e-05 -3.2e-05 0 0</pose>
        <scale>1 1 1</scale>
        <link name='panda_leftfinger'>
          <pose>0.305929 3.2e-05 0.526686 3.14158 0.011861 0.000429</pose>
          <velocity>0.000603 1.2e-05 -0.000599 -0.000292 -0.012091 -0.003853</velocity>
          <acceleration>2.08479 0.003711 -1.19487 -0.904436 0.94741 -1.37593</acceleration>
          <wrench>0.208479 0.000371 -0.119487 0 -0 0</wrench>
        </link>
        <link name='panda_link0'>
          <pose>0 0 3.3e-05 -3.2e-05 0 0</pose>
          <velocity>-2e-06 0 0.006675 -0.006422 2.8e-05 1.3e-05</velocity>
          <acceleration>-0.003284 0.000304 13.349 -0.277766 0.056714 0.025793</acceleration>
          <wrench>-0.010049 0.000931 40.8481 0 -0 0</wrench>
        </link>
        <link name='panda_link1'>
          <pose>0 1.1e-05 0.333033 -3.2e-05 1e-06 1e-05</pose>
          <velocity>0.000192 0.0032 0.006632 -0.006427 0.000273 0.019992</velocity>
          <acceleration>0.025856 2.21074 13.2066 -0.287232 0.546792 2.28813</acceleration>
          <wrench>0.128523 10.9889 65.646 0 -0 0</wrench>
        </link>
        <link name='panda_link2'>
          <pose>0 1e-05 0.333033 -1.57086 -0.785005 5.2e-05</pose>
          <velocity>0.000351 0.002412 0.006965 -0.007203 -0.012621 0.019933</velocity>
          <acceleration>-0.489861 3.54981 12.6928 1.68045 -0.958525 2.17238</acceleration>
          <wrench>-0.316904 2.29646 8.21131 0 -0 0</wrench>
        </link>
        <link name='panda_link3'>
          <pose>-0.223354 1.6e-05 0.556563 -1.5e-05 -0.785016 2.7e-05</pose>
          <velocity>-0.00251 0.001202 0.001966 0.01665 -0.013728 -0.002748</velocity>
          <acceleration>-3.07437 3.51019 10.197 2.51902 -1.41718 -1.11404</acceleration>
          <wrench>-9.92592 11.333 32.922 0 -0 0</wrench>
        </link>
        <link name='panda_link4'>
          <pose>-0.164994 1.8e-05 0.614877 -1.56962 1.55972 -3.14038</pose>
          <velocity>-0.00342 0.001194 0.006383 0.016817 0.015776 0.001619</velocity>
          <acceleration>-3.38052 -0.430975 4.29447 -2.33377 -0.659799 -0.282744</acceleration>
          <wrench>-12.129 -1.54629 15.4081 0 -0 0</wrench>
        </link>
        <link name='panda_link5'>
          <pose>0.219896 3.2e-05 0.693118 -3.13964 1.55972 -3.13961</pose>
          <velocity>-0.001417 -7e-05 -0.002343 -0.000128 0.01528 0.00218</velocity>
          <acceleration>-2.43588 -0.46753 -2.3665 -1.52529 -1.13007 -0.894362</acceleration>
          <wrench>-2.98627 -0.573169 -2.90121 0 -0 0</wrench>
        </link>
        <link name='panda_link6'>
          <pose>0.219896 3.2e-05 0.693118 1.57077 0.011858 3.4e-05</pose>
          <velocity>-0.001471 -0.000243 -0.002512 -0.00024 -0.012984 0.002259</velocity>
          <acceleration>-2.26661 0.040754 -1.91972 -1.97159 -1.07812 -1.35611</acceleration>
          <wrench>-3.77743 0.067919 -3.19932 0 -0 0</wrench>
        </link>
        <link name='panda_link7'>
          <pose>0.30789 3.5e-05 0.692075 3.1332 0.008374 -0.785003</pose>
          <velocity>-0.002524 0.000174 -0.000639 -0.000566 -0.012763 -0.003458</velocity>
          <acceleration>-0.0865 0.069471 -1.06319 -0.49852 -1.15711 -1.80721</acceleration>
          <wrench>-0.126768 0.101811 -1.55813 0 -0 0</wrench>
        </link>
        <link name='panda_rightfinger'>
          <pose>0.305929 3.2e-05 0.526687 3.14158 0.011862 0.000432</pose>
          <velocity>0.000503 2.7e-05 -0.000597 -0.000399 -0.012049 -0.002961</velocity>
          <acceleration>2.2781 0.0216 -1.23099 -0.820494 1.02787 0.188341</acceleration>
          <wrench>0.22781 0.00216 -0.123099 0 -0 0</wrench>
        </link>
      </model>
      <model name='unit_box'>
        <pose>0.54513 0.007373 0.062055 0 -0 0</pose>
        <scale>0.508802 0.494328 0.487764</scale>
        <link name='link'>
          <pose>0.54513 0.007373 0.062055 0 -0 0</pose>
          <velocity>0 0 0 0 -0 0</velocity>
          <acceleration>0 0 0 0 -0 0</acceleration>
          <wrench>0 0 0 0 -0 0</wrench>
        </link>
      </model>
      <light name='sun'>
        <pose>0 0 10 0 -0 0</pose>
      </light>
    </state>
    <model name='unit_box'>
      <link name='link'>
        <inertial>
          <mass>1</mass>
          <inertia>
            <ixx>0.166667</ixx>
            <ixy>0</ixy>
            <ixz>0</ixz>
            <iyy>0.166667</iyy>
            <iyz>0</iyz>
            <izz>0.166667</izz>
          </inertia>
          <pose>0 0 0 0 -0 0</pose>
        </inertial>
        <self_collide>0</self_collide>
        <enable_wind>0</enable_wind>
        <kinematic>0</kinematic>
        <pose>0 0 0 0 -0 0</pose>
        <visual name='visual'>
          <geometry>
            <box>
              <size>1 1 0.999998</size>
            </box>
          </geometry>
          <material>
            <script>
              <name>Gazebo/Grey</name>
              <uri>file://media/materials/scripts/gazebo.material</uri>
            </script>
            <shader type='pixel'/>
          </material>
          <pose>0 0 0 0 -0 0</pose>
          <transparency>0</transparency>
          <cast_shadows>1</cast_shadows>
        </visual>
        <collision name='collision'>
          <laser_retro>0</laser_retro>
          <max_contacts>10</max_contacts>
          <pose>0 0 0 0 -0 0</pose>
          <geometry>
            <box>
              <size>1 1 0.999998</size>
            </box>
          </geometry>
          <surface>
            <friction>
              <ode>
                <mu>1</mu>
                <mu2>1</mu2>
                <fdir1>0 0 0</fdir1>
                <slip1>0</slip1>
                <slip2>0</slip2>
              </ode>
              <torsional>
                <coefficient>1</coefficient>
                <patch_radius>0</patch_radius>
                <surface_radius>0</surface_radius>
                <use_patch_radius>1</use_patch_radius>
                <ode>
                  <slip>0</slip>
                </ode>
              </torsional>
            </friction>
            <bounce>
              <restitution_coefficient>0</restitution_coefficient>
              <threshold>1e+06</threshold>
            </bounce>
            <contact>
              <collide_without_contact>0</collide_without_contact>
              <collide_without_contact_bitmask>1</collide_without_contact_bitmask>
              <collide_bitmask>1</collide_bitmask>
              <ode>
                <soft_cfm>0</soft_cfm>
                <soft_erp>0.2</soft_erp>
                <kp>1e+13</kp>
                <kd>1</kd>
                <max_vel>0.01</max_vel>
                <min_depth>0</min_depth>
              </ode>
              <bullet>
                <split_impulse>1</split_impulse>
                <split_impulse_penetration_threshold>-0.01</split_impulse_penetration_threshold>
                <soft_cfm>0</soft_cfm>
                <soft_erp>0.2</soft_erp>
                <kp>1e+13</kp>
                <kd>1</kd>
              </bullet>
            </contact>
          </surface>
        </collision>
      </link>
      <static>1</static>
      <allow_auto_disable>1</allow_auto_disable>
      <pose>1.21857 0.08905 0.5 0 -0 0</pose>
    </model>
  </world>
</sdf>
